09-02-22 13:25:55 - root - INFO - INICIO DO PROCESSO DE EXPURGO...
09-02-22 13:25:57 - elasticsearch - INFO - GET http://lab.tornis.com.br:9200/_cat/indices/*?h=index&s=index%3Adesc [status:200 request:2.233s]
09-02-22 13:25:57 - elasticsearch - INFO - POST http://lab.tornis.com.br:9200/treino-produtos,treino-produto2,teste/_delete_by_query?wait_for_completion=false [status:200 request:0.326s]
09-02-22 13:25:57 - root - INFO - TAREFA INICIADA, SEGUE TASK_ID: nqj3YV-BQ4m_wUe4eMzVrQ:13773941
09-02-22 13:25:57 - root - INFO - FIM DO PROCESSO DE EXPURGO
09-02-22 13:26:36 - root - INFO - INICIO DO PROCESSO DE EXPURGO...
09-02-22 13:26:38 - elasticsearch - WARNING - GET http://lab.tornis.com.br:9200/_cat/indices/*?h=index&s=index%3Adesc [status:401 request:2.060s]
09-02-22 13:26:38 - root - ERROR - TRACE ----> 
Traceback (most recent call last):
  File "./es-expurgo.py", line 69, in <module>
    results = ex.remove(PERIODO_RETENCAO,INDICES)
  File "./es-expurgo.py", line 41, in remove
    idx = self.getAllIndices(indices)
  File "./es-expurgo.py", line 28, in getAllIndices
    indices = self.es.cat.indices(index=indices,h='index',s='index:desc').split()
  File "/media/tornis/BKP/projetos/prime_system/venv/lib/python3.8/site-packages/elasticsearch/client/utils.py", line 152, in _wrapped
    return func(*args, params=params, headers=headers, **kwargs)
  File "/media/tornis/BKP/projetos/prime_system/venv/lib/python3.8/site-packages/elasticsearch/client/cat.py", line 188, in indices
    return self.transport.perform_request(
  File "/media/tornis/BKP/projetos/prime_system/venv/lib/python3.8/site-packages/elasticsearch/transport.py", line 392, in perform_request
    raise e
  File "/media/tornis/BKP/projetos/prime_system/venv/lib/python3.8/site-packages/elasticsearch/transport.py", line 358, in perform_request
    status, headers_response, data = connection.perform_request(
  File "/media/tornis/BKP/projetos/prime_system/venv/lib/python3.8/site-packages/elasticsearch/connection/http_urllib3.py", line 269, in perform_request
    self._raise_error(response.status, raw_data)
  File "/media/tornis/BKP/projetos/prime_system/venv/lib/python3.8/site-packages/elasticsearch/connection/base.py", line 312, in _raise_error
    raise HTTP_EXCEPTIONS.get(status_code, TransportError)(
elasticsearch.exceptions.AuthenticationException: AuthenticationException(401, 'security_exception', 'missing authentication credentials for REST request [/_cat/indices/*?h=index&s=index%3Adesc]')
09-02-22 13:26:38 - root - INFO - FIM DO PROCESSO DE EXPURGO
09-02-22 13:28:10 - root - INFO - INICIO DO PROCESSO DE EXPURGO...
09-02-22 13:28:10 - elasticsearch - WARNING - GET http://lab.tornis.com.br:9200/_cat/indices/*?h=index&s=index%3Adesc [status:N/A request:0.002s]
Traceback (most recent call last):
  File "/media/tornis/BKP/projetos/prime_system/venv/lib/python3.8/site-packages/urllib3/connection.py", line 174, in _new_conn
    conn = connection.create_connection(
  File "/media/tornis/BKP/projetos/prime_system/venv/lib/python3.8/site-packages/urllib3/util/connection.py", line 72, in create_connection
    for res in socket.getaddrinfo(host, port, family, socket.SOCK_STREAM):
  File "/usr/lib/python3.8/socket.py", line 918, in getaddrinfo
    for res in _socket.getaddrinfo(host, port, family, type, proto, flags):
socket.gaierror: [Errno -5] No address associated with hostname

During handling of the above exception, another exception occurred:

Traceback (most recent call last):
  File "/media/tornis/BKP/projetos/prime_system/venv/lib/python3.8/site-packages/elasticsearch/connection/http_urllib3.py", line 245, in perform_request
    response = self.pool.urlopen(
  File "/media/tornis/BKP/projetos/prime_system/venv/lib/python3.8/site-packages/urllib3/connectionpool.py", line 785, in urlopen
    retries = retries.increment(
  File "/media/tornis/BKP/projetos/prime_system/venv/lib/python3.8/site-packages/urllib3/util/retry.py", line 525, in increment
    raise six.reraise(type(error), error, _stacktrace)
  File "/media/tornis/BKP/projetos/prime_system/venv/lib/python3.8/site-packages/urllib3/packages/six.py", line 770, in reraise
    raise value
  File "/media/tornis/BKP/projetos/prime_system/venv/lib/python3.8/site-packages/urllib3/connectionpool.py", line 703, in urlopen
    httplib_response = self._make_request(
  File "/media/tornis/BKP/projetos/prime_system/venv/lib/python3.8/site-packages/urllib3/connectionpool.py", line 398, in _make_request
    conn.request(method, url, **httplib_request_kw)
  File "/media/tornis/BKP/projetos/prime_system/venv/lib/python3.8/site-packages/urllib3/connection.py", line 239, in request
    super(HTTPConnection, self).request(method, url, body=body, headers=headers)
  File "/usr/lib/python3.8/http/client.py", line 1256, in request
    self._send_request(method, url, body, headers, encode_chunked)
  File "/usr/lib/python3.8/http/client.py", line 1302, in _send_request
    self.endheaders(body, encode_chunked=encode_chunked)
  File "/usr/lib/python3.8/http/client.py", line 1251, in endheaders
    self._send_output(message_body, encode_chunked=encode_chunked)
  File "/usr/lib/python3.8/http/client.py", line 1011, in _send_output
    self.send(msg)
  File "/usr/lib/python3.8/http/client.py", line 951, in send
    self.connect()
  File "/media/tornis/BKP/projetos/prime_system/venv/lib/python3.8/site-packages/urllib3/connection.py", line 205, in connect
    conn = self._new_conn()
  File "/media/tornis/BKP/projetos/prime_system/venv/lib/python3.8/site-packages/urllib3/connection.py", line 186, in _new_conn
    raise NewConnectionError(
urllib3.exceptions.NewConnectionError: <urllib3.connection.HTTPConnection object at 0x7fdd3290aa30>: Failed to establish a new connection: [Errno -5] No address associated with hostname
09-02-22 13:28:10 - elasticsearch - WARNING - GET http://lab.tornis.com.br:9200/_cat/indices/*?h=index&s=index%3Adesc [status:N/A request:0.002s]
Traceback (most recent call last):
  File "/media/tornis/BKP/projetos/prime_system/venv/lib/python3.8/site-packages/urllib3/connection.py", line 174, in _new_conn
    conn = connection.create_connection(
  File "/media/tornis/BKP/projetos/prime_system/venv/lib/python3.8/site-packages/urllib3/util/connection.py", line 72, in create_connection
    for res in socket.getaddrinfo(host, port, family, socket.SOCK_STREAM):
  File "/usr/lib/python3.8/socket.py", line 918, in getaddrinfo
    for res in _socket.getaddrinfo(host, port, family, type, proto, flags):
socket.gaierror: [Errno -5] No address associated with hostname

During handling of the above exception, another exception occurred:

Traceback (most recent call last):
  File "/media/tornis/BKP/projetos/prime_system/venv/lib/python3.8/site-packages/elasticsearch/connection/http_urllib3.py", line 245, in perform_request
    response = self.pool.urlopen(
  File "/media/tornis/BKP/projetos/prime_system/venv/lib/python3.8/site-packages/urllib3/connectionpool.py", line 785, in urlopen
    retries = retries.increment(
  File "/media/tornis/BKP/projetos/prime_system/venv/lib/python3.8/site-packages/urllib3/util/retry.py", line 525, in increment
    raise six.reraise(type(error), error, _stacktrace)
  File "/media/tornis/BKP/projetos/prime_system/venv/lib/python3.8/site-packages/urllib3/packages/six.py", line 770, in reraise
    raise value
  File "/media/tornis/BKP/projetos/prime_system/venv/lib/python3.8/site-packages/urllib3/connectionpool.py", line 703, in urlopen
    httplib_response = self._make_request(
  File "/media/tornis/BKP/projetos/prime_system/venv/lib/python3.8/site-packages/urllib3/connectionpool.py", line 398, in _make_request
    conn.request(method, url, **httplib_request_kw)
  File "/media/tornis/BKP/projetos/prime_system/venv/lib/python3.8/site-packages/urllib3/connection.py", line 239, in request
    super(HTTPConnection, self).request(method, url, body=body, headers=headers)
  File "/usr/lib/python3.8/http/client.py", line 1256, in request
    self._send_request(method, url, body, headers, encode_chunked)
  File "/usr/lib/python3.8/http/client.py", line 1302, in _send_request
    self.endheaders(body, encode_chunked=encode_chunked)
  File "/usr/lib/python3.8/http/client.py", line 1251, in endheaders
    self._send_output(message_body, encode_chunked=encode_chunked)
  File "/usr/lib/python3.8/http/client.py", line 1011, in _send_output
    self.send(msg)
  File "/usr/lib/python3.8/http/client.py", line 951, in send
    self.connect()
  File "/media/tornis/BKP/projetos/prime_system/venv/lib/python3.8/site-packages/urllib3/connection.py", line 205, in connect
    conn = self._new_conn()
  File "/media/tornis/BKP/projetos/prime_system/venv/lib/python3.8/site-packages/urllib3/connection.py", line 186, in _new_conn
    raise NewConnectionError(
urllib3.exceptions.NewConnectionError: <urllib3.connection.HTTPConnection object at 0x7fdd3290afd0>: Failed to establish a new connection: [Errno -5] No address associated with hostname
09-02-22 13:28:10 - elasticsearch - WARNING - GET http://lab.tornis.com.br:9200/_cat/indices/*?h=index&s=index%3Adesc [status:N/A request:0.002s]
Traceback (most recent call last):
  File "/media/tornis/BKP/projetos/prime_system/venv/lib/python3.8/site-packages/urllib3/connection.py", line 174, in _new_conn
    conn = connection.create_connection(
  File "/media/tornis/BKP/projetos/prime_system/venv/lib/python3.8/site-packages/urllib3/util/connection.py", line 72, in create_connection
    for res in socket.getaddrinfo(host, port, family, socket.SOCK_STREAM):
  File "/usr/lib/python3.8/socket.py", line 918, in getaddrinfo
    for res in _socket.getaddrinfo(host, port, family, type, proto, flags):
socket.gaierror: [Errno -5] No address associated with hostname

During handling of the above exception, another exception occurred:

Traceback (most recent call last):
  File "/media/tornis/BKP/projetos/prime_system/venv/lib/python3.8/site-packages/elasticsearch/connection/http_urllib3.py", line 245, in perform_request
    response = self.pool.urlopen(
  File "/media/tornis/BKP/projetos/prime_system/venv/lib/python3.8/site-packages/urllib3/connectionpool.py", line 785, in urlopen
    retries = retries.increment(
  File "/media/tornis/BKP/projetos/prime_system/venv/lib/python3.8/site-packages/urllib3/util/retry.py", line 525, in increment
    raise six.reraise(type(error), error, _stacktrace)
  File "/media/tornis/BKP/projetos/prime_system/venv/lib/python3.8/site-packages/urllib3/packages/six.py", line 770, in reraise
    raise value
  File "/media/tornis/BKP/projetos/prime_system/venv/lib/python3.8/site-packages/urllib3/connectionpool.py", line 703, in urlopen
    httplib_response = self._make_request(
  File "/media/tornis/BKP/projetos/prime_system/venv/lib/python3.8/site-packages/urllib3/connectionpool.py", line 398, in _make_request
    conn.request(method, url, **httplib_request_kw)
  File "/media/tornis/BKP/projetos/prime_system/venv/lib/python3.8/site-packages/urllib3/connection.py", line 239, in request
    super(HTTPConnection, self).request(method, url, body=body, headers=headers)
  File "/usr/lib/python3.8/http/client.py", line 1256, in request
    self._send_request(method, url, body, headers, encode_chunked)
  File "/usr/lib/python3.8/http/client.py", line 1302, in _send_request
    self.endheaders(body, encode_chunked=encode_chunked)
  File "/usr/lib/python3.8/http/client.py", line 1251, in endheaders
    self._send_output(message_body, encode_chunked=encode_chunked)
  File "/usr/lib/python3.8/http/client.py", line 1011, in _send_output
    self.send(msg)
  File "/usr/lib/python3.8/http/client.py", line 951, in send
    self.connect()
  File "/media/tornis/BKP/projetos/prime_system/venv/lib/python3.8/site-packages/urllib3/connection.py", line 205, in connect
    conn = self._new_conn()
  File "/media/tornis/BKP/projetos/prime_system/venv/lib/python3.8/site-packages/urllib3/connection.py", line 186, in _new_conn
    raise NewConnectionError(
urllib3.exceptions.NewConnectionError: <urllib3.connection.HTTPConnection object at 0x7fdd329131f0>: Failed to establish a new connection: [Errno -5] No address associated with hostname
09-02-22 13:28:10 - elasticsearch - WARNING - GET http://lab.tornis.com.br:9200/_cat/indices/*?h=index&s=index%3Adesc [status:N/A request:0.002s]
Traceback (most recent call last):
  File "/media/tornis/BKP/projetos/prime_system/venv/lib/python3.8/site-packages/urllib3/connection.py", line 174, in _new_conn
    conn = connection.create_connection(
  File "/media/tornis/BKP/projetos/prime_system/venv/lib/python3.8/site-packages/urllib3/util/connection.py", line 72, in create_connection
    for res in socket.getaddrinfo(host, port, family, socket.SOCK_STREAM):
  File "/usr/lib/python3.8/socket.py", line 918, in getaddrinfo
    for res in _socket.getaddrinfo(host, port, family, type, proto, flags):
socket.gaierror: [Errno -5] No address associated with hostname

During handling of the above exception, another exception occurred:

Traceback (most recent call last):
  File "/media/tornis/BKP/projetos/prime_system/venv/lib/python3.8/site-packages/elasticsearch/connection/http_urllib3.py", line 245, in perform_request
    response = self.pool.urlopen(
  File "/media/tornis/BKP/projetos/prime_system/venv/lib/python3.8/site-packages/urllib3/connectionpool.py", line 785, in urlopen
    retries = retries.increment(
  File "/media/tornis/BKP/projetos/prime_system/venv/lib/python3.8/site-packages/urllib3/util/retry.py", line 525, in increment
    raise six.reraise(type(error), error, _stacktrace)
  File "/media/tornis/BKP/projetos/prime_system/venv/lib/python3.8/site-packages/urllib3/packages/six.py", line 770, in reraise
    raise value
  File "/media/tornis/BKP/projetos/prime_system/venv/lib/python3.8/site-packages/urllib3/connectionpool.py", line 703, in urlopen
    httplib_response = self._make_request(
  File "/media/tornis/BKP/projetos/prime_system/venv/lib/python3.8/site-packages/urllib3/connectionpool.py", line 398, in _make_request
    conn.request(method, url, **httplib_request_kw)
  File "/media/tornis/BKP/projetos/prime_system/venv/lib/python3.8/site-packages/urllib3/connection.py", line 239, in request
    super(HTTPConnection, self).request(method, url, body=body, headers=headers)
  File "/usr/lib/python3.8/http/client.py", line 1256, in request
    self._send_request(method, url, body, headers, encode_chunked)
  File "/usr/lib/python3.8/http/client.py", line 1302, in _send_request
    self.endheaders(body, encode_chunked=encode_chunked)
  File "/usr/lib/python3.8/http/client.py", line 1251, in endheaders
    self._send_output(message_body, encode_chunked=encode_chunked)
  File "/usr/lib/python3.8/http/client.py", line 1011, in _send_output
    self.send(msg)
  File "/usr/lib/python3.8/http/client.py", line 951, in send
    self.connect()
  File "/media/tornis/BKP/projetos/prime_system/venv/lib/python3.8/site-packages/urllib3/connection.py", line 205, in connect
    conn = self._new_conn()
  File "/media/tornis/BKP/projetos/prime_system/venv/lib/python3.8/site-packages/urllib3/connection.py", line 186, in _new_conn
    raise NewConnectionError(
urllib3.exceptions.NewConnectionError: <urllib3.connection.HTTPConnection object at 0x7fdd32913a00>: Failed to establish a new connection: [Errno -5] No address associated with hostname
09-02-22 13:28:10 - root - ERROR - TRACE ----> 
Traceback (most recent call last):
  File "/media/tornis/BKP/projetos/prime_system/venv/lib/python3.8/site-packages/urllib3/connection.py", line 174, in _new_conn
    conn = connection.create_connection(
  File "/media/tornis/BKP/projetos/prime_system/venv/lib/python3.8/site-packages/urllib3/util/connection.py", line 72, in create_connection
    for res in socket.getaddrinfo(host, port, family, socket.SOCK_STREAM):
  File "/usr/lib/python3.8/socket.py", line 918, in getaddrinfo
    for res in _socket.getaddrinfo(host, port, family, type, proto, flags):
socket.gaierror: [Errno -5] No address associated with hostname

During handling of the above exception, another exception occurred:

Traceback (most recent call last):
  File "/media/tornis/BKP/projetos/prime_system/venv/lib/python3.8/site-packages/elasticsearch/connection/http_urllib3.py", line 245, in perform_request
    response = self.pool.urlopen(
  File "/media/tornis/BKP/projetos/prime_system/venv/lib/python3.8/site-packages/urllib3/connectionpool.py", line 785, in urlopen
    retries = retries.increment(
  File "/media/tornis/BKP/projetos/prime_system/venv/lib/python3.8/site-packages/urllib3/util/retry.py", line 525, in increment
    raise six.reraise(type(error), error, _stacktrace)
  File "/media/tornis/BKP/projetos/prime_system/venv/lib/python3.8/site-packages/urllib3/packages/six.py", line 770, in reraise
    raise value
  File "/media/tornis/BKP/projetos/prime_system/venv/lib/python3.8/site-packages/urllib3/connectionpool.py", line 703, in urlopen
    httplib_response = self._make_request(
  File "/media/tornis/BKP/projetos/prime_system/venv/lib/python3.8/site-packages/urllib3/connectionpool.py", line 398, in _make_request
    conn.request(method, url, **httplib_request_kw)
  File "/media/tornis/BKP/projetos/prime_system/venv/lib/python3.8/site-packages/urllib3/connection.py", line 239, in request
    super(HTTPConnection, self).request(method, url, body=body, headers=headers)
  File "/usr/lib/python3.8/http/client.py", line 1256, in request
    self._send_request(method, url, body, headers, encode_chunked)
  File "/usr/lib/python3.8/http/client.py", line 1302, in _send_request
    self.endheaders(body, encode_chunked=encode_chunked)
  File "/usr/lib/python3.8/http/client.py", line 1251, in endheaders
    self._send_output(message_body, encode_chunked=encode_chunked)
  File "/usr/lib/python3.8/http/client.py", line 1011, in _send_output
    self.send(msg)
  File "/usr/lib/python3.8/http/client.py", line 951, in send
    self.connect()
  File "/media/tornis/BKP/projetos/prime_system/venv/lib/python3.8/site-packages/urllib3/connection.py", line 205, in connect
    conn = self._new_conn()
  File "/media/tornis/BKP/projetos/prime_system/venv/lib/python3.8/site-packages/urllib3/connection.py", line 186, in _new_conn
    raise NewConnectionError(
urllib3.exceptions.NewConnectionError: <urllib3.connection.HTTPConnection object at 0x7fdd32913a00>: Failed to establish a new connection: [Errno -5] No address associated with hostname

During handling of the above exception, another exception occurred:

Traceback (most recent call last):
  File "./es-expurgo.py", line 69, in <module>
    results = ex.remove(PERIODO_RETENCAO,INDICES)
  File "./es-expurgo.py", line 41, in remove
    idx = self.getAllIndices(indices)
  File "./es-expurgo.py", line 28, in getAllIndices
    indices = self.es.cat.indices(index=indices,h='index',s='index:desc').split()
  File "/media/tornis/BKP/projetos/prime_system/venv/lib/python3.8/site-packages/elasticsearch/client/utils.py", line 152, in _wrapped
    return func(*args, params=params, headers=headers, **kwargs)
  File "/media/tornis/BKP/projetos/prime_system/venv/lib/python3.8/site-packages/elasticsearch/client/cat.py", line 188, in indices
    return self.transport.perform_request(
  File "/media/tornis/BKP/projetos/prime_system/venv/lib/python3.8/site-packages/elasticsearch/transport.py", line 390, in perform_request
    raise e
  File "/media/tornis/BKP/projetos/prime_system/venv/lib/python3.8/site-packages/elasticsearch/transport.py", line 358, in perform_request
    status, headers_response, data = connection.perform_request(
  File "/media/tornis/BKP/projetos/prime_system/venv/lib/python3.8/site-packages/elasticsearch/connection/http_urllib3.py", line 258, in perform_request
    raise ConnectionError("N/A", str(e), e)
elasticsearch.exceptions.ConnectionError: ConnectionError(<urllib3.connection.HTTPConnection object at 0x7fdd32913a00>: Failed to establish a new connection: [Errno -5] No address associated with hostname) caused by: NewConnectionError(<urllib3.connection.HTTPConnection object at 0x7fdd32913a00>: Failed to establish a new connection: [Errno -5] No address associated with hostname)
09-02-22 13:28:10 - root - INFO - FIM DO PROCESSO DE EXPURGO
09-02-22 13:28:40 - root - INFO - INICIO DO PROCESSO DE EXPURGO...
09-02-22 13:28:42 - elasticsearch - INFO - GET http://lab.tornis.com.br:9200/_cat/indices/*?h=index&s=index%3Adesc [status:200 request:1.499s]
09-02-22 13:28:42 - elasticsearch - INFO - POST http://lab.tornis.com.br:9200/treino-produtos,treino-produto2,teste/_delete_by_query?wait_for_completion=false [status:200 request:0.631s]
09-02-22 13:28:42 - root - INFO - TAREFA INICIADA, SEGUE TASK_ID: nqj3YV-BQ4m_wUe4eMzVrQ:13778144
09-02-22 13:28:42 - root - INFO - FIM DO PROCESSO DE EXPURGO
09-02-22 13:38:17 - root - INFO - INICIO DO PROCESSO DE EXPURGO...
09-02-22 13:38:19 - elasticsearch - INFO - GET http://lab.tornis.com.br:9200/_cat/indices/*?h=index&s=index%3Adesc [status:200 request:2.564s]
09-02-22 13:38:20 - elasticsearch - INFO - POST http://lab.tornis.com.br:9200/treino-produtos,treino-produto2,teste/_delete_by_query?wait_for_completion=false [status:200 request:0.577s]
09-02-22 13:38:20 - root - INFO - TAREFA INICIADA, SEGUE TASK_ID: nqj3YV-BQ4m_wUe4eMzVrQ:13792762
09-02-22 13:38:20 - root - INFO - FIM DO PROCESSO DE EXPURGO
